Workbook

Sheet Overview
A1: Habit Tracking & Goal Setting Apps — Competitive Feature Matrix
A3: Purpose | B3: Market study to inform building a competing app
A4: Platform scope | B4: Apple App Store (iOS/iPadOS/watchOS/macOS)
A5: Ranking method | B5: App Store review count used as market-size proxy (higher = larger active base)
A6: Apps covered | B6: Top 10 apps by review volume capture the clear majority of the category
A7: Date compiled | B7: April 2026
A9: Sheet guide
A10: Apps & Market Data | B10: One row per app: developer, pricing, review count, rating, platforms
A11: Feature Matrix | B11: Features as rows, apps as columns. Y / N / P (partial) / ? (unverified)
A12: Feature Gaps | B12: Aggregated view — where the market is over- vs under-served
A13: Positioning | B13: Segments & archetypes to help identify whitespace
A15: Legend
A16: Y | B16: Yes — feature is present
A17: N | B17: No — feature is absent
A18: P | B18: Partial — limited, paywalled, or implemented in restricted form
A19: ? | B19: Unverified from public sources
A21: Source caveat | B21: Feature data compiled from App Store listings, developer sites, and independent reviews (Zapier, Reclaim, Tool Finder, Mindful Suite, Reddit, Apple App Store reviews). Some cells reflect marketed features rather than verified user-observed behavior. Flag cells marked 'P' for hands-on verification before making strategic decisions.
A23: Key methodological notes
A24: 1 | B24: Review counts are a lagging indicator of market size — a new entrant (e.g., Habi) may have low counts but high engagement.
A25: 2 | B25: Finch is included despite being primarily 'self-care' because its goal-tracker and habit-building features compete directly and it is the volume leader.
A26: 3 | B26: TickTick and Todoist are included because they contain full habit trackers as sub-modules, making them competitors even if primarily task managers.
A27: 4 | B27: Habitica's 15M+ downloads (claimed) do not match its ~2K App Store review count — this is because most usage is on Android and web.

Sheet Apps & Market Data
A1: Rank | B1: App | C1: Developer | D1: iOS Rating | E1: iOS Review Count (approx.) | F1: Pricing Model | G1: Free Tier Limit | H1: Premium Price (annual) | I1: Platforms | J1: Category Positioning
A2: 1 | B2: Finch: Self-Care Pet | C2: Finch Care PBC | D2: 4.9 | E2: 670,000+ | F2: Freemium | G2: Generous — most features free | H2: $14.99 (iOS) / $69.99 (Android) | I2: iOS, iPadOS, Android | J2: Gamified self-care with pet companion
A3: 2 | B3: Fabulous: Daily Habit Tracker | C3: Fabulous | D3: 4.6 | E3: 75,600+ | F3: Freemium (subscription) | G3: Limited — basic journeys only | H3: $39.99 | I3: iOS, Android | J3: Coaching-led, behavioral-science routines
A4: 3 | B4: Productive — Habit Tracker | C4: Apalon / Mosaic | D4: 4 | E4: 82,000+ | F4: Freemium (subscription) | G4: 2–3 habits | H4: ~$23 (often $12 promo) | I4: iOS only | J4: Time-block habit organization
A5: 4 | B5: Streaks | C5: Crunchy Bagel | D5: 4.8 | E5: 27,000+ | F5: Paid (one-time) | G5: N/A — paid app | H5: $5.99 one-time | I5: iOS, iPadOS, macOS, watchOS, visionOS | J5: Minimalist Apple-ecosystem tracker
A6: 5 | B6: Habitify: Habit Tracker | C6: Unstatic Ltd | D6: 4.6 | E6: 152,000+ | F6: Freemium (subscription) | G6: 3 habits | H6: ~$35 / $64.99 lifetime | I6: iOS, iPadOS, macOS, watchOS, Android, Web | J6: Cross-platform data-driven tracker
A7: 6 | B7: TickTick: To Do List & Calendar | C7: Appest Inc. | D7: 4.8 | E7: 150,000+ | F7: Freemium (subscription) | G7: 5 habits (within task app) | H7: ~$35.99 | I7: iOS, Android, macOS, Windows, Web, watchOS | J7: Task manager with habit module
A8: 7 | B8: Way of Life | C8: Way of Life ehf | D8: 4.5 | E8: 5,000+ | F8: Freemium | G8: 3 habits | H8: ~$4.99/mo (iPhone) | I8: iOS, Android | J8: Fast-log color-coded journal
A9: 8 | B9: Strides: Habit Tracker + Goals | C9: Goals LLC | D9: 4.7 | E9: 7,800+ | F9: Freemium (subscription) | G9: Unlimited habits, limited trackers | H9: ~$39.99 | I9: iOS, iPadOS, macOS, watchOS | J9: SMART-goal + multi-tracker-type
A10: 9 | B10: Habit Tracker (InnerGrow) | C10: InnerGrow | D10: 4.8 | E10: 250,000+ | F10: Freemium (subscription) | G10: 5–6 habits | H10: ~$29.99 / lifetime option | I10: iOS, Android | J10: General-purpose tracker with group habits
A11: 10 | B11: Habitica | C11: HabitRPG | D11: 4 | E11: 2,000+ | F11: Freemium (subscription) | G11: Free core game | H11: ~$47.99 | I11: iOS, Android, Web | J11: Gamified RPG with social guilds

Sheet Feature Matrix
A1: Category | B1: Feature | C1: Finch | D1: Fabulous | E1: Productive | F1: Streaks | G1: Habitify | H1: TickTick | I1: Way of Life | J1: Strides | K1: Habit Tracker (InnerGrow) | L1: Habitica
A2: CORE TRACKING
B3: Unlimited habits (free tier) | C3: N | D3: N | E3: N | F3: N | G3: N | H3: N | I3: N | J3: P | K3: N | L3: Y
B4: Unlimited habits (premium) | C4: Y | D4: Y | E4: Y | F4: Y | G4: Y | H4: Y | I4: Y | J4: Y | K4: Y | L4: Y
B5: Positive habits (build) | C5: Y | D5: Y | E5: Y | F5: Y | G5: Y | H5: Y | I5: Y | J5: Y | K5: Y | L5: Y
B6: Negative habits (break/quit) | C6: Y | D6: N | E6: N | F6: Y | G6: Y | H6: N | I6: Y | J6: Y | K6: Y | L6: Y
B7: Quantitative habits (e.g., 8 glasses) | C7: Y | D7: N | E7: Y | F7: Y | G7: Y | H7: N | I7: P | J7: Y | K7: Y | L7: N
B8: Timed habits (duration-based) | C8: Y | D8: Y | E8: Y | F8: Y | G8: Y | H8: Y | I8: N | J8: Y | K8: Y | L8: N
B9: Multiple completions per day | C9: Y | D9: Y | E9: Y | F9: Y | G9: Y | H9: P | I9: N | J9: Y | K9: Y | L9: Y
B10: Flexible scheduling (days/week, X per week) | C10: Y | D10: Y | E10: Y | F10: Y | G10: Y | H10: Y | I10: Y | J10: Y | K10: Y | L10: Y
B11: Skip/pause days without breaking streak | C11: Y | D11: P | E11: Y | F11: Y | G11: P | H11: P | I11: Y | J11: Y | K11: Y | L11: N
B12: Back-date / log past entries | C12: Y | D12: P | E12: Y | F12: Y | G12: Y | H12: Y | I12: Y | J12: Y | K12: Y | L12: P
A13: STREAKS & GAMIFICATION
B14: Streak counter (days in a row) | C14: Y | D14: Y | E14: Y | F14: Y | G14: Y | H14: Y | I14: Y | J14: Y | K14: Y | L14: P
B15: Streak freeze / protection | C15: N | D15: N | E15: N | F15: N | G15: N | H15: N | I15: N | J15: N | K15: N | L15: P
B16: Best-ever streak record | C16: Y | D16: P | E16: Y | F16: Y | G16: Y | H16: Y | I16: Y | J16: Y | K16: Y | L16: N
B17: XP / levels / avatar progression | C17: Y | D17: N | E17: N | F17: N | G17: N | H17: Y | I17: N | J17: N | K17: N | L17: Y
B18: Virtual pet / companion | C18: Y | D18: N | E18: N | F18: N | G18: N | H18: N | I18: N | J18: N | K18: N | L18: P
B19: In-app currency / rewards store | C19: Y | D19: N | E19: N | F19: N | G19: N | H19: Y | I19: N | J19: N | K19: N | L19: Y
B20: Badges / achievements | C20: Y | D20: Y | E20: Y | F20: P | G20: Y | H20: Y | I20: N | J20: N | K20: Y | L20: Y
B21: Challenges (timed programs) | C21: Y | D21: Y | E21: Y | F21: N | G21: Y | H21: N | I21: N | J21: N | K21: Y | L21: Y
A22: GOAL SETTING
B23: Long-term goal objects (distinct from habits) | C23: Y | D23: Y | E23: N | F23: N | G23: N | H23: Y | I23: N | J23: Y | K23: N | L23: N
B24: SMART goal framework | C24: N | D24: P | E24: N | F24: N | G24: N | H24: N | I24: N | J24: Y | K24: N | L24: N
B25: Milestones / sub-goals | C25: Y | D25: Y | E25: N | F25: N | G25: N | H25: Y | I25: N | J25: Y | K25: N | L25: N
B26: Goals linked to habits | C26: Y | D26: Y | E26: N | F26: N | G26: P | H26: Y | I26: N | J26: Y | K26: N | L26: N
B27: Goal deadline / target-date tracking | C27: Y | D27: P | E27: N | F27: N | G27: N | H27: Y | I27: N | J27: Y | K27: N | L27: N
B28: Vision board / imagery | C28: N | D28: N | E28: N | F28: N | G28: N | H28: N | I28: N | J28: N | K28: N | L28: N
A29: REMINDERS & NOTIFICATIONS
B30: Time-based reminders | C30: Y | D30: Y | E30: Y | F30: Y | G30: Y | H30: Y | I30: Y | J30: Y | K30: Y | L30: Y
B31: Multiple reminders per habit | C31: Y | D31: Y | E31: Y | F31: Y | G31: Y | H31: Y | I31: N | J31: Y | K31: Y | L31: P
B32: Location-based reminders | C32: N | D32: N | E32: Y | F32: N | G32: N | H32: Y | I32: N | J32: N | K32: Y | L32: N
B33: Smart / adaptive reminders (AI) | C33: P | D33: Y | E33: N | F33: N | G33: N | H33: N | I33: N | J33: N | K33: N | L33: N
B34: Repeated / escalating reminders | C34: N | D34: N | E34: Y | F34: N | G34: Y | H34: N | I34: N | J34: N | K34: Y | L34: N
A35: VISUALIZATION & ANALYTICS
B36: Calendar heatmap / contribution grid | C36: P | D36: N | E36: Y | F36: Y | G36: Y | H36: Y | I36: Y | J36: Y | K36: Y | L36: N
B37: Weekly / monthly / yearly reports | C37: Y | D37: Y | E37: Y | F37: Y | G37: Y | H37: Y | I37: Y | J37: Y | K37: Y | L37: P
B38: Completion rate % | C38: Y | D38: Y | E38: Y | F38: Y | G38: Y | H38: Y | I38: Y | J38: Y | K38: Y | L38: N
B39: Trend charts / line graphs | C39: Y | D39: P | E39: Y | F39: P | G39: Y | H39: P | I39: Y | J39: Y | K39: Y | L39: N
B40: Pattern / correlation insights | C40: Y | D40: Y | E40: P | F40: N | G40: Y | H40: N | I40: Y | J40: P | K40: N | L40: N
...

Sheet Feature Gaps
A1: Feature | B1: # Yes | C1: # Partial | D1: # No | E1: Market Penetration | F1: Whitespace Signal
A2: CORE TRACKING
A3: Unlimited habits (free tier) | B3: =COUNTIF('Feature Matrix'!C3:L3,"Y") -> 1 | C3: =COUNTIF('Feature Matrix'!C3:L3,"P") -> 1 | D3: =COUNTIF('Feature Matrix'!C3:L3,"N") -> 8 | E3: =(B3+0.5*C3)/10 -> 0.15 | F3: =IF(E3<0.3,"High — underserved",IF(E3<=0.7,"Medium — differentiator","Low — table stakes")) -> High — underserved
A4: Unlimited habits (premium) | B4: =COUNTIF('Feature Matrix'!C4:L4,"Y") -> 10 | C4: =COUNTIF('Feature Matrix'!C4:L4,"P") -> 0 | D4: =COUNTIF('Feature Matrix'!C4:L4,"N") -> 0 | E4: =(B4+0.5*C4)/10 -> 1 | F4: =IF(E4<0.3,"High — underserved",IF(E4<=0.7,"Medium — differentiator","Low — table stakes")) -> Low — table stakes
A5: Positive habits (build) | B5: =COUNTIF('Feature Matrix'!C5:L5,"Y") -> 10 | C5: =COUNTIF('Feature Matrix'!C5:L5,"P") -> 0 | D5: =COUNTIF('Feature Matrix'!C5:L5,"N") -> 0 | E5: =(B5+0.5*C5)/10 -> 1 | F5: =IF(E5<0.3,"High — underserved",IF(E5<=0.7,"Medium — differentiator","Low — table stakes")) -> Low — table stakes
A6: Negative habits (break/quit) | B6: =COUNTIF('Feature Matrix'!C6:L6,"Y") -> 7 | C6: =COUNTIF('Feature Matrix'!C6:L6,"P") -> 0 | D6: =COUNTIF('Feature Matrix'!C6:L6,"N") -> 3 | E6: =(B6+0.5*C6)/10 -> 0.7 | F6: =IF(E6<0.3,"High — underserved",IF(E6<=0.7,"Medium — differentiator","Low — table stakes")) -> Medium — differentiator
A7: Quantitative habits (e.g., 8 glasses) | B7: =COUNTIF('Feature Matrix'!C7:L7,"Y") -> 6 | C7: =COUNTIF('Feature Matrix'!C7:L7,"P") -> 1 | D7: =COUNTIF('Feature Matrix'!C7:L7,"N") -> 3 | E7: =(B7+0.5*C7)/10 -> 0.65 | F7: =IF(E7<0.3,"High — underserved",IF(E7<=0.7,"Medium — differentiator","Low — table stakes")) -> Medium — differentiator
A8: Timed habits (duration-based) | B8: =COUNTIF('Feature Matrix'!C8:L8,"Y") -> 8 | C8: =COUNTIF('Feature Matrix'!C8:L8,"P") -> 0 | D8: =COUNTIF('Feature Matrix'!C8:L8,"N") -> 2 | E8: =(B8+0.5*C8)/10 -> 0.8 | F8: =IF(E8<0.3,"High — underserved",IF(E8<=0.7,"Medium — differentiator","Low — table stakes")) -> Low — table stakes
A9: Multiple completions per day | B9: =COUNTIF('Feature Matrix'!C9:L9,"Y") -> 8 | C9: =COUNTIF('Feature Matrix'!C9:L9,"P") -> 1 | D9: =COUNTIF('Feature Matrix'!C9:L9,"N") -> 1 | E9: =(B9+0.5*C9)/10 -> 0.85 | F9: =IF(E9<0.3,"High — underserved",IF(E9<=0.7,"Medium — differentiator","Low — table stakes")) -> Low — table stakes
A10: Flexible scheduling (days/week, X per week) | B10: =COUNTIF('Feature Matrix'!C10:L10,"Y") -> 10 | C10: =COUNTIF('Feature Matrix'!C10:L10,"P") -> 0 | D10: =COUNTIF('Feature Matrix'!C10:L10,"N") -> 0 | E10: =(B10+0.5*C10)/10 -> 1 | F10: =IF(E10<0.3,"High — underserved",IF(E10<=0.7,"Medium — differentiator","Low — table stakes")) -> Low — table stakes
A11: Skip/pause days without breaking streak | B11: =COUNTIF('Feature Matrix'!C11:L11,"Y") -> 6 | C11: =COUNTIF('Feature Matrix'!C11:L11,"P") -> 3 | D11: =COUNTIF('Feature Matrix'!C11:L11,"N") -> 1 | E11: =(B11+0.5*C11)/10 -> 0.75 | F11: =IF(E11<0.3,"High — underserved",IF(E11<=0.7,"Medium — differentiator","Low — table stakes")) -> Low — table stakes
A12: Back-date / log past entries | B12: =COUNTIF('Feature Matrix'!C12:L12,"Y") -> 8 | C12: =COUNTIF('Feature Matrix'!C12:L12,"P") -> 2 | D12: =COUNTIF('Feature Matrix'!C12:L12,"N") -> 0 | E12: =(B12+0.5*C12)/10 -> 0.9 | F12: =IF(E12<0.3,"High — underserved",IF(E12<=0.7,"Medium — differentiator","Low — table stakes")) -> Low — table stakes
A13: STREAKS & GAMIFICATION
A14: Streak counter (days in a row) | B14: =COUNTIF('Feature Matrix'!C14:L14,"Y") -> 9 | C14: =COUNTIF('Feature Matrix'!C14:L14,"P") -> 1 | D14: =COUNTIF('Feature Matrix'!C14:L14,"N") -> 0 | E14: =(B14+0.5*C14)/10 -> 0.95 | F14: =IF(E14<0.3,"High — underserved",IF(E14<=0.7,"Medium — differentiator","Low — table stakes")) -> Low — table stakes
A15: Streak freeze / protection | B15: =COUNTIF('Feature Matrix'!C15:L15,"Y") -> 0 | C15: =COUNTIF('Feature Matrix'!C15:L15,"P") -> 1 | D15: =COUNTIF('Feature Matrix'!C15:L15,"N") -> 9 | E15: =(B15+0.5*C15)/10 -> 0.05 | F15: =IF(E15<0.3,"High — underserved",IF(E15<=0.7,"Medium — differentiator","Low — table stakes")) -> High — underserved
A16: Best-ever streak record | B16: =COUNTIF('Feature Matrix'!C16:L16,"Y") -> 8 | C16: =COUNTIF('Feature Matrix'!C16:L16,"P") -> 1 | D16: =COUNTIF('Feature Matrix'!C16:L16,"N") -> 1 | E16: =(B16+0.5*C16)/10 -> 0.85 | F16: =IF(E16<0.3,"High — underserved",IF(E16<=0.7,"Medium — differentiator","Low — table stakes")) -> Low — table stakes
A17: XP / levels / avatar progression | B17: =COUNTIF('Feature Matrix'!C17:L17,"Y") -> 3 | C17: =COUNTIF('Feature Matrix'!C17:L17,"P") -> 0 | D17: =COUNTIF('Feature Matrix'!C17:L17,"N") -> 7 | E17: =(B17+0.5*C17)/10 -> 0.3 | F17: =IF(E17<0.3,"High — underserved",IF(E17<=0.7,"Medium — differentiator","Low — table stakes")) -> Medium — differentiator
A18: Virtual pet / companion | B18: =COUNTIF('Feature Matrix'!C18:L18,"Y") -> 1 | C18: =COUNTIF('Feature Matrix'!C18:L18,"P") -> 1 | D18: =COUNTIF('Feature Matrix'!C18:L18,"N") -> 8 | E18: =(B18+0.5*C18)/10 -> 0.15 | F18: =IF(E18<0.3,"High — underserved",IF(E18<=0.7,"Medium — differentiator","Low — table stakes")) -> High — underserved
A19: In-app currency / rewards store | B19: =COUNTIF('Feature Matrix'!C19:L19,"Y") -> 3 | C19: =COUNTIF('Feature Matrix'!C19:L19,"P") -> 0 | D19: =COUNTIF('Feature Matrix'!C19:L19,"N") -> 7 | E19: =(B19+0.5*C19)/10 -> 0.3 | F19: =IF(E19<0.3,"High — underserved",IF(E19<=0.7,"Medium — differentiator","Low — table stakes")) -> Medium — differentiator
A20: Badges / achievements | B20: =COUNTIF('Feature Matrix'!C20:L20,"Y") -> 7 | C20: =COUNTIF('Feature Matrix'!C20:L20,"P") -> 1 | D20: =COUNTIF('Feature Matrix'!C20:L20,"N") -> 2 | E20: =(B20+0.5*C20)/10 -> 0.75 | F20: =IF(E20<0.3,"High — underserved",IF(E20<=0.7,"Medium — differentiator","Low — table stakes")) -> Low — table stakes
A21: Challenges (timed programs) | B21: =COUNTIF('Feature Matrix'!C21:L21,"Y") -> 6 | C21: =COUNTIF('Feature Matrix'!C21:L21,"P") -> 0 | D21: =COUNTIF('Feature Matrix'!C21:L21,"N") -> 4 | E21: =(B21+0.5*C21)/10 -> 0.6 | F21: =IF(E21<0.3,"High — underserved",IF(E21<=0.7,"Medium — differentiator","Low — table stakes")) -> Medium — differentiator
A22: GOAL SETTING
A23: Long-term goal objects (distinct from habits) | B23: =COUNTIF('Feature Matrix'!C23:L23,"Y") -> 4 | C23: =COUNTIF('Feature Matrix'!C23:L23,"P") -> 0 | D23: =COUNTIF('Feature Matrix'!C23:L23,"N") -> 6 | E23: =(B23+0.5*C23)/10 -> 0.4 | F23: =IF(E23<0.3,"High — underserved",IF(E23<=0.7,"Medium — differentiator","Low — table stakes")) -> Medium — differentiator
A24: SMART goal framework | B24: =COUNTIF('Feature Matrix'!C24:L24,"Y") -> 1 | C24: =COUNTIF('Feature Matrix'!C24:L24,"P") -> 1 | D24: =COUNTIF('Feature Matrix'!C24:L24,"N") -> 8 | E24: =(B24+0.5*C24)/10 -> 0.15 | F24: =IF(E24<0.3,"High — underserved",IF(E24<=0.7,"Medium — differentiator","Low — table stakes")) -> High — underserved
A25: Milestones / sub-goals | B25: =COUNTIF('Feature Matrix'!C25:L25,"Y") -> 4 | C25: =COUNTIF('Feature Matrix'!C25:L25,"P") -> 0 | D25: =COUNTIF('Feature Matrix'!C25:L25,"N") -> 6 | E25: =(B25+0.5*C25)/10 -> 0.4 | F25: =IF(E25<0.3,"High — underserved",IF(E25<=0.7,"Medium — differentiator","Low — table stakes")) -> Medium — differentiator
A26: Goals linked to habits | B26: =COUNTIF('Feature Matrix'!C26:L26,"Y") -> 4 | C26: =COUNTIF('Feature Matrix'!C26:L26,"P") -> 1 | D26: =COUNTIF('Feature Matrix'!C26:L26,"N") -> 5 | E26: =(B26+0.5*C26)/10 -> 0.45 | F26: =IF(E26<0.3,"High — underserved",IF(E26<=0.7,"Medium — differentiator","Low — table stakes")) -> Medium — differentiator
A27: Goal deadline / target-date tracking | B27: =COUNTIF('Feature Matrix'!C27:L27,"Y") -> 3 | C27: =COUNTIF('Feature Matrix'!C27:L27,"P") -> 1 | D27: =COUNTIF('Feature Matrix'!C27:L27,"N") -> 6 | E27: =(B27+0.5*C27)/10 -> 0.35 | F27: =IF(E27<0.3,"High — underserved",IF(E27<=0.7,"Medium — differentiator","Low — table stakes")) -> Medium — differentiator
A28: Vision board / imagery | B28: =COUNTIF('Feature Matrix'!C28:L28,"Y") -> 0 | C28: =COUNTIF('Feature Matrix'!C28:L28,"P") -> 0 | D28: =COUNTIF('Feature Matrix'!C28:L28,"N") -> 10 | E28: =(B28+0.5*C28)/10 -> 0 | F28: =IF(E28<0.3,"High — underserved",IF(E28<=0.7,"Medium — differentiator","Low — table stakes")) -> High — underserved
A29: REMINDERS & NOTIFICATIONS
A30: Time-based reminders | B30: =COUNTIF('Feature Matrix'!C30:L30,"Y") -> 10 | C30: =COUNTIF('Feature Matrix'!C30:L30,"P") -> 0 | D30: =COUNTIF('Feature Matrix'!C30:L30,"N") -> 0 | E30: =(B30+0.5*C30)/10 -> 1 | F30: =IF(E30<0.3,"High — underserved",IF(E30<=0.7,"Medium — differentiator","Low — table stakes")) -> Low — table stakes
A31: Multiple reminders per habit | B31: =COUNTIF('Feature Matrix'!C31:L31,"Y") -> 8 | C31: =COUNTIF('Feature Matrix'!C31:L31,"P") -> 1 | D31: =COUNTIF('Feature Matrix'!C31:L31,"N") -> 1 | E31: =(B31+0.5*C31)/10 -> 0.85 | F31: =IF(E31<0.3,"High — underserved",IF(E31<=0.7,"Medium — differentiator","Low — table stakes")) -> Low — table stakes
A32: Location-based reminders | B32: =COUNTIF('Feature Matrix'!C32:L32,"Y") -> 3 | C32: =COUNTIF('Feature Matrix'!C32:L32,"P") -> 0 | D32: =COUNTIF('Feature Matrix'!C32:L32,"N") -> 7 | E32: =(B32+0.5*C32)/10 -> 0.3 | F32: =IF(E32<0.3,"High — underserved",IF(E32<=0.7,"Medium — differentiator","Low — table stakes")) -> Medium — differentiator
A33: Smart / adaptive reminders (AI) | B33: =COUNTIF('Feature Matrix'!C33:L33,"Y") -> 1 | C33: =COUNTIF('Feature Matrix'!C33:L33,"P") -> 1 | D33: =COUNTIF('Feature Matrix'!C33:L33,"N") -> 8 | E33: =(B33+0.5*C33)/10 -> 0.15 | F33: =IF(E33<0.3,"High — underserved",IF(E33<=0.7,"Medium — differentiator","Low — table stakes")) -> High — underserved
A34: Repeated / escalating reminders | B34: =COUNTIF('Feature Matrix'!C34:L34,"Y") -> 3 | C34: =COUNTIF('Feature Matrix'!C34:L34,"P") -> 0 | D34: =COUNTIF('Feature Matrix'!C34:L34,"N") -> 7 | E34: =(B34+0.5*C34)/10 -> 0.3 | F34: =IF(E34<0.3,"High — underserved",IF(E34<=0.7,"Medium — differentiator","Low — table stakes")) -> Medium — differentiator
A35: VISUALIZATION & ANALYTICS
A36: Calendar heatmap / contribution grid | B36: =COUNTIF('Feature Matrix'!C36:L36,"Y") -> 7 | C36: =COUNTIF('Feature Matrix'!C36:L36,"P") -> 1 | D36: =COUNTIF('Feature Matrix'!C36:L36,"N") -> 2 | E36: =(B36+0.5*C36)/10 -> 0.75 | F36: =IF(E36<0.3,"High — underserved",IF(E36<=0.7,"Medium — differentiator","Low — table stakes")) -> Low — table stakes
A37: Weekly / monthly / yearly reports | B37: =COUNTIF('Feature Matrix'!C37:L37,"Y") -> 9 | C37: =COUNTIF('Feature Matrix'!C37:L37,"P") -> 1 | D37: =COUNTIF('Feature Matrix'!C37:L37,"N") -> 0 | E37: =(B37+0.5*C37)/10 -> 0.95 | F37: =IF(E37<0.3,"High — underserved",IF(E37<=0.7,"Medium — differentiator","Low — table stakes")) -> Low — table stakes
A38: Completion rate % | B38: =COUNTIF('Feature Matrix'!C38:L38,"Y") -> 9 | C38: =COUNTIF('Feature Matrix'!C38:L38,"P") -> 0 | D38: =COUNTIF('Feature Matrix'!C38:L38,"N") -> 1 | E38: =(B38+0.5*C38)/10 -> 0.9 | F38: =IF(E38<0.3,"High — underserved",IF(E38<=0.7,"Medium — differentiator","Low — table stakes")) -> Low — table stakes
A39: Trend charts / line graphs | B39: =COUNTIF('Feature Matrix'!C39:L39,"Y") -> 6 | C39: =COUNTIF('Feature Matrix'!C39:L39,"P") -> 3 | D39: =COUNTIF('Feature Matrix'!C39:L39,"N") -> 1 | E39: =(B39+0.5*C39)/10 -> 0.75 | F39: =IF(E39<0.3,"High — underserved",IF(E39<=0.7,"Medium — differentiator","Low — table stakes")) -> Low — table stakes
A40: Pattern / correlation insights | B40: =COUNTIF('Feature Matrix'!C40:L40,"Y") -> 4 | C40: =COUNTIF('Feature Matrix'!C40:L40,"P") -> 2 | D40: =COUNTIF('Feature Matrix'!C40:L40,"N") -> 4 | E40: =(B40+0.5*C40)/10 -> 0.5 | F40: =IF(E40<0.3,"High — underserved",IF(E40<=0.7,"Medium — differentiator","Low — table stakes")) -> Medium — differentiator
...

Sheet Positioning
A1: Archetype | B1: Apps in this cluster | C1: Core value prop | D1: Demographic | E1: Notable gap / opportunity
A2: Gamified Companion | B2: Finch, Habitica | C2: Emotional engagement via pets/avatars; rewards are intrinsic to the product | D2: Gen Z, neurodivergent users, anyone with low baseline motivation | E2: Little serious analytics; limited for performance/athletic users
A3: Minimalist Apple-first | B3: Streaks, Way of Life | C3: Fewest taps, beautiful design, deep Apple ecosystem | D3: Apple power users, design-conscious professionals | E3: Weak social/accountability; no AI; capped habit counts
A4: Data-Driven Cross-Platform | B4: Habitify, Habit Tracker (InnerGrow) | C4: Deep analytics, cross-device sync, integrations | D4: Productivity nerds, Android+iOS households | E4: Interfaces are utilitarian — limited emotional pull
A5: Coaching / Behavior-Science | B5: Fabulous, Productive | C5: Guided journeys, curated content, CBT-adjacent structure | D5: Users seeking lifestyle transformation, not just logging | E5: Heavy paywalls; feels like a content app not a tool
A6: Goal-Setting SMART | B6: Strides, (Habitify partial) | C6: Long-term goals with milestones, not just daily checks | D6: Career-focused adults, athletes, students | E6: Narrow feature set, weak design, no AI goal decomposition
A7: Task Manager with Habits | B7: TickTick | C7: Habits bolted onto a full GTD system | D7: Power-user professionals consolidating tools | E7: Habit module is secondary — not best-in-class
A9: WHITESPACE SUMMARY (from Feature Gaps sheet)
A10: High-penetration = table stakes | B10: Streak counters, time reminders, completion %, widgets, themes, cloud sync
A11: Medium-penetration = differentiators | B11: Apple Health write, negative habits, CSV export, calendar integrations, mood tracking, challenges
A12: Low-penetration = whitespace | B12: AI coach, streak freezes, SMART goal framework, human coaching, E2E encryption, vision boards, location reminders, adaptive AI reminders, Health two-way sync
A14: STRATEGIC OBSERVATIONS FOR A NEW ENTRANT
A15: 1. Pricing anomaly | B15: Finch charges $14.99/yr on iOS but $69.99/yr on Android — there is room for transparent/consistent pricing as a marketing hook
A16: 2. Streak-freeze gap | B16: Virtually no major app offers intelligent streak protection — Habi (new entrant) built its whole positioning around this. Validates the gap.
A17: 3. Goal-habit linkage | B17: Only 3 apps explicitly link goals to habits. Users currently patch this with Notion. Large whitespace.
A18: 4. AI is under-exploited | B18: Only Fabulous has a real AI coach. Given 2025–26 LLM economics, a modern AI habit coach with adaptive scheduling is undertaken by no incumbent.
A19: 5. Apple Health two-way | B19: Only Habitify and Streaks do it well. Differentiator for fitness-oriented users.
A20: 6. Consolidation threat | B20: TickTick already bundles habits into a task manager. A well-designed habit app must justify why it's not a sub-feature of Todoist/TickTick/Reminders.
A21: 7. Gamification fatigue | B21: Habitica's 4.0 rating (vs Finch's 4.9) suggests pixel-RPG gamification is dated. Finch's pet/emotional model is the new gold standard.
